<?xml version="1.0" encoding="utf-8"?>
<!-- This URDF was automatically created by SolidWorks to URDF Exporter! Originally created by Stephen Brawner (brawner@gmail.com) 
     Commit Version: 1.5.1-0-g916b5db  Build Version: 1.5.7152.31018
     For more information, please see http://wiki.ros.org/sw_urdf_exporter -->
<robot
  name="ur5_description">
  <link
    name="base_link">
    <inertial>
      <origin
        xyz="2.2379E-05 -0.00077074 0.010876"
        rpy="0 0 0" />
      <mass
        value="0.34861" />
      <inertia
        ixx="0.00045733"
        ixy="7.2083E-08"
        ixz="5.4072E-08"
        iyy="0.00042831"
        iyz="-5.9393E-07"
        izz="0.00085476" />
    </inertial>
    <visual>
      <origin
        xyz="0 0 0"
        rpy="0 0 0" />
      <geometry>
        <mesh
          filename="package://ur5_description/meshes/base_link.STL" />
      </geometry>
      <material
        name="">
        <color
          rgba="1 1 1 1" />
      </material>
    </visual>
    <collision>
      <origin
        xyz="0 0 0"
        rpy="0 0 0" />
      <geometry>
        <mesh
          filename="package://ur5_description/meshes/base_link.STL" />
      </geometry>
    </collision>
  </link>
  <link
    name="link_1">
    <inertial>
      <origin
        xyz="1.8316E-06 0.063328 -0.0092426"
        rpy="0 0 0" />
      <mass
        value="1.556" />
      <inertia
        ixx="0.0028144"
        ixy="-3.5877E-08"
        ixz="-2.053E-08"
        iyy="0.0030181"
        iyz="0.00041338"
        izz="0.0025808" />
    </inertial>
    <visual>
      <origin
        xyz="0 0 0"
        rpy="0 0 0" />
      <geometry>
        <mesh
          filename="package://ur5_description/meshes/link_1.STL" />
      </geometry>
      <material
        name="">
        <color
          rgba="0.79216 0.81961 0.93333 1" />
      </material>
    </visual>
    <collision>
      <origin
        xyz="0 0 0"
        rpy="0 0 0" />
      <geometry>
        <mesh
          filename="package://ur5_description/meshes/link_1.STL" />
      </geometry>
    </collision>
  </link>
  <joint
    name="joint_1"
    type="revolute">
    <origin
      xyz="0 0 0.024"
      rpy="1.5708 0 0" />
    <parent
      link="base_link" />
    <child
      link="link_1" />
    <axis
      xyz="0 -1 0" />
    <limit
      lower="-3.14"
      upper="3.14"
      effort="150"
      velocity="3.14" />
  </joint>
  <link
    name="link_2">
    <inertial>
      <origin
        xyz="-6.9975481714835E-09 0.212500774803063 -0.0641198851376631"
        rpy="0 0 0" />
      <mass
        value="5.39321385176719" />
      <inertia
        ixx="0.0229052047363308"
        ixy="-3.80485736402523E-08"
        ixz="-1.33095715729492E-09"
        iyy="0.00808975921379843"
        iyz="-5.25735080933302E-10"
        izz="0.0233126134438523" />
    </inertial>
    <visual>
      <origin
        xyz="0 0 0"
        rpy="0 0 0" />
      <geometry>
        <mesh
          filename="package://ur5_description/meshes/link_2.STL" />
      </geometry>
      <material
        name="">
        <color
          rgba="0.333333333333333 0.862745098039216 1 1" />
      </material>
    </visual>
    <collision>
      <origin
        xyz="0 0 0"
        rpy="0 0 0" />
      <geometry>
        <mesh
          filename="package://ur5_description/meshes/link_2.STL" />
      </geometry>
    </collision>
  </link>
  <joint
    name="joint_2"
    type="revolute">
    <origin
      xyz="0 0.0652 -0.0705"
      rpy="0 0 0" />
    <parent
      link="link_1" />
    <child
      link="link_2" />
    <axis
      xyz="0 0 1" />
    <limit
      lower="-3.14"
      upper="3.14"
      effort="150"
      velocity="3.14" />
  </joint>
  <link
    name="link_3">
    <inertial>
      <origin
        xyz="4.48591355879564E-08 0.184385161816603 0.0500891493611347"
        rpy="0 0 0" />
      <mass
        value="2.51858519755964" />
      <inertia
        ixx="0.00958504077999387"
        ixy="4.148722095138E-08"
        ixz="6.14723476893109E-09"
        iyy="0.00217646355290865"
        iyz="-0.00015208461045435"
        izz="0.00967914820040632" />
    </inertial>
    <visual>
      <origin
        xyz="0 0 0"
        rpy="0 0 0" />
      <geometry>
        <mesh
          filename="package://ur5_description/meshes/link_3.STL" />
      </geometry>
      <material
        name="">
        <color
          rgba="0.792156862745098 0.819607843137255 0.933333333333333 1" />
      </material>
    </visual>
    <collision>
      <origin
        xyz="0 0 0"
        rpy="0 0 0" />
      <geometry>
        <mesh
          filename="package://ur5_description/meshes/link_3.STL" />
      </geometry>
    </collision>
  </link>
  <joint
    name="joint_3"
    type="revolute">
    <origin
      xyz="0 0.425 0"
      rpy="0 0 0" />
    <parent
      link="link_2" />
    <child
      link="link_3" />
    <axis
      xyz="0 0 1" />
    <limit
      lower="-3.14"
      upper="3.14"
      effort="150"
      velocity="3.14" />
  </joint>
  <link
    name="link_4">
    <inertial>
      <origin
        xyz="0.000267439864317399 -0.00317622153547115 -0.0410560934864477"
        rpy="0 0 0" />
      <mass
        value="0.515206254007367" />
      <inertia
        ixx="0.000399706734339536"
        ixy="-2.82972081805418E-10"
        ixz="-9.65116686398988E-09"
        iyy="0.000407751087898542"
        iyz="5.63390381941324E-05"
        izz="0.000372352818817745" />
    </inertial>
    <visual>
      <origin
        xyz="0 0 0"
        rpy="0 0 0" />
      <geometry>
        <mesh
          filename="package://ur5_description/meshes/link_4.STL" />
      </geometry>
      <material
        name="">
        <color
          rgba="0.792156862745098 0.819607843137255 0.933333333333333 1" />
      </material>
    </visual>
    <collision>
      <origin
        xyz="0 0 0"
        rpy="0 0 0" />
      <geometry>
        <mesh
          filename="package://ur5_description/meshes/link_4.STL" />
      </geometry>
    </collision>
  </link>
  <joint
    name="joint_4"
    type="revolute">
    <origin
      xyz="0 0.39243 0.007"
      rpy="0 0 0" />
    <parent
      link="link_3" />
    <child
      link="link_4" />
    <axis
      xyz="0 0 -1" />
    <limit
      lower="-3.14"
      upper="3.14"
      effort="150"
      velocity="3.14" />
  </joint>
  <link
    name="link_5">
    <inertial>
      <origin
        xyz="7.83854854126579E-05 0.041077285875557 0.00362613301231042"
        rpy="0 0 0" />
      <mass
        value="0.514944791822967" />
      <inertia
        ixx="0.000399268233437844"
        ixy="5.80168826194153E-09"
        ixz="-4.61368287522735E-09"
        iyy="0.000372230714889473"
        iyz="5.62591191055601E-05"
        izz="0.000407328693172721" />
    </inertial>
    <visual>
      <origin
        xyz="0 0 0"
        rpy="0 0 0" />
      <geometry>
        <mesh
          filename="package://ur5_description/meshes/link_5.STL" />
      </geometry>
      <material
        name="">
        <color
          rgba="0.792156862745098 0.819607843137255 0.933333333333333 1" />
      </material>
    </visual>
    <collision>
      <origin
        xyz="0 0 0"
        rpy="0 0 0" />
      <geometry>
        <mesh
          filename="package://ur5_description/meshes/link_5.STL" />
      </geometry>
    </collision>
  </link>
  <joint
    name="joint_5"
    type="revolute">
    <origin
      xyz="0.00026549 0.047898 -0.0455"
      rpy="0 0 0" />
    <parent
      link="link_4" />
    <child
      link="link_5" />
    <axis
      xyz="0 1 0" />
    <limit
      lower="-3.14"
      upper="3.14"
      effort="150"
      velocity="3.14" />
  </joint>
  <link
    name="link_6">
    <inertial>
      <origin
        xyz="1.259858710466E-09 6.22572740960337E-05 -0.0157714392324549"
        rpy="0 0 0" />
      <mass
        value="0.137899158818492" />
      <inertia
        ixx="5.98863552131521E-05"
        ixy="-5.2187246790267E-12"
        ixz="-1.57401817933674E-13"
        iyy="5.95416899053166E-05"
        iyz="-6.61913792737833E-09"
        izz="9.55326593779328E-05" />
    </inertial>
    <visual>
      <origin
        xyz="0 0 0"
        rpy="0 0 0" />
      <geometry>
        <mesh
          filename="package://ur5_description/meshes/link_6.STL" />
      </geometry>
      <material
        name="">
        <color
          rgba="0.898039215686275 0.917647058823529 0.929411764705882 1" />
      </material>
    </visual>
    <collision>
      <origin
        xyz="0 0 0"
        rpy="0 0 0" />
      <geometry>
        <mesh
          filename="package://ur5_description/meshes/link_6.STL" />
      </geometry>
    </collision>
  </link>
  <joint
    name="joint_6"
    type="revolute">
    <origin
      xyz="7.9254E-05 0.0455 -0.047451"
      rpy="0 0 0" />
    <parent
      link="link_5" />
    <child
      link="link_6" />
    <axis
      xyz="0 0 -1" />
    <limit
      lower="-3.14"
      upper="3.14"
      effort="150"
      velocity="3.14" />
  </joint>
</robot>
